Workbook
Name res_Nov23.: data!$A$2:$D$29162

Sheet pivot
A3: Sum of value | B3: Column Labels
A4: Row Labels | B4: (blank) | C4: cumulative-IPC | D4: instructions | E4: cycles | F4: L1D-USEFUL | G4: L1D-USELESS | H4: L1I-USEFUL | I4: L1I-USELESS | J4: L2C-USEFUL | K4: L2C-USELESS | L4: LLC-USEFUL | M4: LLC-USELESS | N4: disp-0 | O4: disp-1 | P4: disp-2 | Q4: disp-3 | R4: disp-4 | S4: disp-5 | T4: disp-6 | U4: disp-7 | V4: disp-8 | W4: disp-9 | X4: disp-10 | Y4: disp-11 | Z4: disp-12 | AA4: disp-13 | AB4: disp-14 | AC4: disp-15 | AD4: disp-16 | AE4: disp-17 | AF4: disp-18 | AG4: disp-19 | AH4: disp-20 | AI4: disp-21 | AJ4: disp-22 | AK4: disp-23 | AL4: disp-24 | AM4: disp-25 | AN4: disp-26 | AO4: disp-27 | AP4: disp-28 | AQ4: disp-29 | AR4: disp-30 | AS4: disp-31 | AT4: disp-32 | AU4: disp-33 | AV4: disp-34 | AW4: disp-35 | AX4: disp-36 | AY4: disp-37 | AZ4: disp-38 | BA4: disp-39 | BB4: disp-40 | BC4: disp-41 | BD4: disp-42 | BE4: disp-43 | BF4: disp-44 | BG4: disp-45 | BH4: disp-46 | BI4: disp-47 | BJ4: disp-48 | BK4: disp-49 | BL4: disp-50 | BM4: disp-51 | BN4: disp-52 | BO4: disp-53 | BP4: disp-54 | BQ4: disp-55 | BR4: disp-56 | BS4: disp-57 | BT4: disp-58 | BU4: disp-59 | BV4: disp-60 | BW4: disp-61 | BX4: disp-62 | BY4: disp-63 | BZ4: disp-64 | CA4: disp-65 | CB4: total_mispredicts | CC4: diffBits-0 | CD4: diffBits-1 | CE4: diffBits-2 | CF4: diffBits-3 | CG4: diffBits-4 | CH4: diffBits-5 | CI4: diffBits-6 | CJ4: diffBits-7 | CK4: diffBits-8 | CL4: diffBits-9 | CM4: diffBits-10 | CN4: diffBits-11 | CO4: diffBits-12 | CP4: diffBits-13 | CQ4: diffBits-14 | CR4: diffBits-15 | CS4: diffBits-16 | CT4: diffBits-17 | CU4: diffBits-18 | CV4: diffBits-19 | CW4: diffBits-20 | CX4: diffBits-21 | CY4: diffBits-22 | CZ4: diffBits-23 | DA4: diffBits-24 | DB4: diffBits-25 | DC4: diffBits-26 | DD4: diffBits-27 | DE4: diffBits-28 | DF4: diffBits-29 | DG4: diffBits-30 | DH4: diffBits-31 | DI4: diffBits-32 | DJ4: diffBits-33 | DK4: diffBits-34 | DL4: diffBits-35 | DM4: diffBits-36 | DN4: diffBits-37 | DO4: diffBits-38 | DP4: diffBits-39 | DQ4: diffBits-40 | DR4: diffBits-41 | DS4: diffBits-42 | DT4: diffBits-43 | DU4: diffBits-44 | DV4: diffBits-45 | DW4: diffBits-46 | DX4: diffBits-47 | DY4: diffBits-48 | DZ4: diffBits-49 | EA4: diffBits-50 | EB4: diffBits-51 | EC4: diffBits-52 | ED4: diffBits-53 | EE4: diffBits-54 | EF4: diffBits-55 | EG4: diffBits-56 | EH4: diffBits-57 | EI4: diffBits-58 | EJ4: diffBits-59 | EK4: diffBits-60 | EL4: diffBits-61 | EM4: diffBits-62 | EN4: diffBits-63 | EO4: diffBits-64 | EP4: diffBits-65 | EQ4: BTB_4D_Hits | ER4: BTB_6D_Hits | ES4: BTB_8D_Hits | ET4: BTB_12D_Hits | EU4: BTB_18D_Hits | EV4: BTB_25D_Hits | EW4: BTB_46D_Hits | EX4: BTB_Ret_Hits | EY4: BTB_4D_Misses | EZ4: BTB_6D_Misses | FA4: BTB_8D_Misses | FB4: BTB_12D_Misses | FC4: BTB_18D_Misses | FD4: BTB_25D_Misses | FE4: BTB_46D_Misses | FF4: BTB_Ret_Misses | FG4: total_direction_mispredicts | FH4: total_target_mispredicts1 | FI4: total_target_mispredicts2 | FJ4: mispredict_on_btb_hit | FK4: NOT_BRANCH: | FL4: BRANCH_DIRECT_JUMP: | FM4: BRANCH_INDIRECT: | FN4: BRANCH_CONDITIONAL: | FO4: BRANCH_DIRECT_CALL: | FP4: BRANCH_INDIRECT_CALL: | FQ4: BRANCH_RETURN: | FR4: BRANCH_OTHER: | FS4: BTB_reads: | FT4: BTB_writes: | FU4: PageBTB_reads: | FV4: PageBTB_writes: | FW4: PageBTB_readsBeforeWrite: | FX4: RegionBTB_reads: | FY4: RegionBTB_writes: | FZ4: RegionBTB_readsBeforeWrite: | GA4: Num_unique_branches | GB4: Grand Total
A5: (blank)
A6: (blank)
A7: (blank) Total
A8: client_001
A9: no_BTBX | C9: 0.999102 | D9: 50000003 | E9: 50044928 | F9: 134862 | G9: 253541 | H9: 0 | I9: 0 | J9: 14306 | K9: 127209 | L9: 31497 | M9: 90396 | CB9: 421055 | EQ9: 597915 | ER9: 978422 | ES9: 590782 | ET9: 494765 | EU9: 354189 | EV9: 385275 | EW9: 4163 | EX9: 720758 | EY9: 100262 | EZ9: 3612 | FA9: 39945 | FB9: 326 | FC9: 3290 | FD9: 253 | FE9: 194 | FF9: 2802 | FG9: 163031 | FH9: 110663 | FI9: 147361 | FJ9: 107340 | FK9: 0 | FL9: 0 | FM9: 6288 | FN9: 0 | FO9: 0 | FP9: 55444 | FQ9: 45608 | FR9: 0 | FS9: 5181420 | FT9: 1223 | FU9: 0 | FV9: 0 | FW9: 0 | FX9: 0 | FY9: 0 | FZ9: 0 | GA9: 7708 | GB9: 1.1122084e+08
A10: fdip_BTBX | C10: 1.03678 | D10: 50000003 | E10: 48226457 | F10: 130820 | G10: 253391 | H10: 102658 | I10: 41550 | J10: 16110 | K10: 138501 | L10: 29902 | M10: 97266 | N10: 1439710 | O10: 0 | P10: 932 | Q10: 617057 | R10: 986168 | S10: 947322 | T10: 1120852 | U10: 880375 | V10: 623804 | W10: 304971 | X10: 188595 | Y10: 56844 | Z10: 30297 | AA10: 38724 | AB10: 98325 | AC10: 38246 | AD10: 17284 | AE10: 51977 | AF10: 66683 | AG10: 225881 | AH10: 219617 | AI10: 298040 | AJ10: 305781 | AK10: 44847 | AL10: 0 | AM10: 0 | AN10: 0 | AO10: 9359 | AP10: 0 | AQ10: 0 | AR10: 0 | AS10: 0 | AT10: 0 | AU10: 0 | AV10: 0 | AW10: 0 | AX10: 0 | AY10: 0 | AZ10: 0 | BA10: 0 | BB10: 0 | BC10: 0 | BD10: 0 | BE10: 0 | BF10: 0 | BG10: 0 | BH10: 0 | BI10: 0 | BJ10: 0 | BK10: 0 | BL10: 0 | BM10: 0 | BN10: 0 | BO10: 0 | BP10: 0 | BQ10: 0 | BR10: 0 | BS10: 0 | BT10: 0 | BU10: 0 | BV10: 0 | BW10: 0 | BX10: 0 | BY10: 0 | BZ10: 0 | CA10: 0 | CB10: 634957 | CC10: 1439710 | CD10: 506 | CE10: 362293 | CF10: 350362 | CG10: 724575 | CH10: 1041876 | CI10: 1132643 | CJ10: 509269 | CK10: 383316 | CL10: 387504 | CM10: 487589 | CN10: 241393 | CO10: 96023 | CP10: 23123 | CQ10: 42129 | CR10: 68812 | CS10: 84677 | CT10: 68050 | CU10: 118834 | CV10: 68240 | CW10: 255228 | CX10: 203619 | CY10: 505808 | CZ10: 6753 | DA10: 0 | DB10: 0 | DC10: 0 | DD10: 9359 | DE10: 0 | DF10: 0 | DG10: 0 | DH10: 0 | DI10: 0 | DJ10: 0 | DK10: 0 | DL10: 0 | DM10: 0 | DN10: 0 | DO10: 0 | DP10: 0 | DQ10: 0 | DR10: 0 | DS10: 0 | DT10: 0 | DU10: 0 | DV10: 0 | DW10: 0 | DX10: 0 | DY10: 0 | DZ10: 0 | EA10: 0 | EB10: 0 | EC10: 0 | ED10: 0 | EE10: 0 | EF10: 0 | EG10: 0 | EH10: 0 | EI10: 0 | EJ10: 0 | EK10: 0 | EL10: 0 | EM10: 0 | EN10: 0 | EO10: 0 | EP10: 0 | EQ10: 561315 | ER10: 913419 | ES10: 566899 | ET10: 490005 | EU10: 354190 | EV10: 385279 | EW10: 4163 | EX10: 716465 | EY10: 136860 | EZ10: 31056 | FA10: 89648 | FB10: 12064 | FC10: 6942 | FD10: 1362 | FE10: 194 | FF10: 7097 | FG10: 158201 | FH10: 202378 | FI10: 274378 | FJ10: 191533 | FK10: 0 | FL10: 0 | FM10: 6288 | FN10: 0 | FO10: 0 | FP10: 55444 | FQ10: 129801 | FR10: 0 | FS10: 50347478 | FT10: 1223 | FU10: 0 | FV10: 0 | FW10: 0 | FX10: 0 | FY10: 0 | FZ10: 0 | GA10: 7708 | GB10: 1.7254639e+08
A11: fdip_convBTB | C11: 1.03678 | D11: 50000003 | E11: 48226171 | F11: 130685 | G11: 253397 | H11: 103271 | I11: 41847 | J11: 16049 | K11: 138754 | L11: 29876 | M11: 97169 | N11: 1439710 | O11: 0 | P11: 932 | Q11: 617057 | R11: 986168 | S11: 947322 | T11: 1120852 | U11: 880375 | V11: 623804 | W11: 304971 | X11: 188595 | Y11: 56844 | Z11: 30297 | AA11: 38724 | AB11: 98325 | AC11: 38246 | AD11: 17284 | AE11: 51977 | AF11: 66683 | AG11: 225881 | AH11: 219617 | AI11: 298040 | AJ11: 305781 | AK11: 44847 | AL11: 0 | AM11: 0 | AN11: 0 | AO11: 9359 | AP11: 0 | AQ11: 0 | AR11: 0 | AS11: 0 | AT11: 0 | AU11: 0 | AV11: 0 | AW11: 0 | AX11: 0 | AY11: 0 | AZ11: 0 | BA11: 0 | BB11: 0 | BC11: 0 | BD11: 0 | BE11: 0 | BF11: 0 | BG11: 0 | BH11: 0 | BI11: 0 | BJ11: 0 | BK11: 0 | BL11: 0 | BM11: 0 | BN11: 0 | BO11: 0 | BP11: 0 | BQ11: 0 | BR11: 0 | BS11: 0 | BT11: 0 | BU11: 0 | BV11: 0 | BW11: 0 | BX11: 0 | BY11: 0 | BZ11: 0 | CA11: 0 | CB11: 638279 | CC11: 1439710 | CD11: 506 | CE11: 362293 | CF11: 350362 | CG11: 724575 | CH11: 1041876 | CI11: 1132643 | CJ11: 509269 | CK11: 383316 | CL11: 387504 | CM11: 487589 | CN11: 241393 | CO11: 96023 | CP11: 23123 | CQ11: 42129 | CR11: 68812 | CS11: 84677 | CT11: 68050 | CU11: 118834 | CV11: 68240 | CW11: 255228 | CX11: 203619 | CY11: 505808 | CZ11: 6753 | DA11: 0 | DB11: 0 | DC11: 0 | DD11: 9359 | DE11: 0 | DF11: 0 | DG11: 0 | DH11: 0 | DI11: 0 | DJ11: 0 | DK11: 0 | DL11: 0 | DM11: 0 | DN11: 0 | DO11: 0 | DP11: 0 | DQ11: 0 | DR11: 0 | DS11: 0 | DT11: 0 | DU11: 0 | DV11: 0 | DW11: 0 | DX11: 0 | DY11: 0 | DZ11: 0 | EA11: 0 | EB11: 0 | EC11: 0 | ED11: 0 | EE11: 0 | EF11: 0 | EG11: 0 | EH11: 0 | EI11: 0 | EJ11: 0 | EK11: 0 | EL11: 0 | EM11: 0 | EN11: 0 | EO11: 0 | EP11: 0 | EQ11: 559983 | ER11: 910490 | ES11: 566572 | ET11: 489547 | EU11: 354215 | EV11: 385300 | EW11: 4164 | EX11: 716417 | EY11: 138192 | EZ11: 32617 | FA11: 91311 | FB11: 12096 | FC11: 7386 | FD11: 1357 | FE11: 166 | FF11: 7145 | FG11: 156308 | FH11: 202557 | FI11: 279414 | FJ11: 191701 | FK11: 0 | FL11: 1 | FM11: 6288 | FN11: 0 | FO11: 0 | FP11: 55447 | FQ11: 129965 | FR11: 0 | FS11: 50610454 | FT11: 2336326 | FU11: 0 | FV11: 0 | FW11: 0 | FX11: 0 | FY11: 0 | FZ11: 0 | GA11: 7708 | GB11: 1.7515201e+08
A12: fdip_pdede | C12: 1.03438 | D12: 50000003 | E12: 48338234 | F12: 130892 | G12: 253430 | H12: 100539 | I12: 40503 | J12: 16072 | K12: 138343 | L12: 29905 | M12: 98440 | N12: 1439710 | O12: 0 | P12: 932 | Q12: 617057 | R12: 986168 | S12: 947322 | T12: 1120852 | U12: 880375 | V12: 623804 | W12: 304971 | X12: 188595 | Y12: 56844 | Z12: 30297 | AA12: 38724 | AB12: 98325 | AC12: 38246 | AD12: 17284 | AE12: 51977 | AF12: 66683 | AG12: 225881 | AH12: 219617 | AI12: 298040 | AJ12: 305781 | AK12: 44847 | AL12: 0 | AM12: 0 | AN12: 0 | AO12: 9359 | AP12: 0 | AQ12: 0 | AR12: 0 | AS12: 0 | AT12: 0 | AU12: 0 | AV12: 0 | AW12: 0 | AX12: 0 | AY12: 0 | AZ12: 0 | BA12: 0 | BB12: 0 | BC12: 0 | BD12: 0 | BE12: 0 | BF12: 0 | BG12: 0 | BH12: 0 | BI12: 0 | BJ12: 0 | BK12: 0 | BL12: 0 | BM12: 0 | BN12: 0 | BO12: 0 | BP12: 0 | BQ12: 0 | BR12: 0 | BS12: 0 | BT12: 0 | BU12: 0 | BV12: 0 | BW12: 0 | BX12: 0 | BY12: 0 | BZ12: 0 | CA12: 0 | CB12: 630865 | CC12: 1439710 | CD12: 506 | CE12: 362293 | CF12: 350362 | CG12: 724575 | CH12: 1041876 | CI12: 1132643 | CJ12: 509269 | CK12: 383316 | CL12: 387504 | CM12: 487589 | CN12: 241393 | CO12: 96023 | CP12: 23123 | CQ12: 42129 | CR12: 68812 | CS12: 84677 | CT12: 68050 | CU12: 118834 | CV12: 68240 | CW12: 255228 | CX12: 203619 | CY12: 505808 | CZ12: 6753 | DA12: 0 | DB12: 0 | DC12: 0 | DD12: 9359 | DE12: 0 | DF12: 0 | DG12: 0 | DH12: 0 | DI12: 0 | DJ12: 0 | DK12: 0 | DL12: 0 | DM12: 0 | DN12: 0 | DO12: 0 | DP12: 0 | DQ12: 0 | DR12: 0 | DS12: 0 | DT12: 0 | DU12: 0 | DV12: 0 | DW12: 0 | DX12: 0 | DY12: 0 | DZ12: 0 | EA12: 0 | EB12: 0 | EC12: 0 | ED12: 0 | EE12: 0 | EF12: 0 | EG12: 0 | EH12: 0 | EI12: 0 | EJ12: 0 | EK12: 0 | EL12: 0 | EM12: 0 | EN12: 0 | EO12: 0 | EP12: 0 | EQ12: 561311 | ER12: 913382 | ES12: 566883 | ET12: 491141 | EU12: 354197 | EV12: 385293 | EW12: 4164 | EX12: 718900 | EY12: 136864 | EZ12: 31093 | FA12: 89655 | FB12: 12073 | FC12: 6961 | FD12: 210 | FE12: 169 | FF12: 4662 | FG12: 158193 | FH12: 199383 | FI12: 273289 | FJ12: 190985 | FK12: 0 | FL12: 0 | FM12: 6288 | FN12: 0 | FO12: 0 | FP12: 55447 | FQ12: 129250 | FR12: 0 | FS12: 46855349 | FT12: 1255 | FU12: 2298450 | FV12: 23 | FW12: 471 | FX12: 2298450 | FY12: 0 | FZ12: 471 | GA12: 7708 | GB12: 1.7375258e+08
A13: no_convBTB | C13: 0.998769 | D13: 50000003 | E13: 50061640 | F13: 134869 | G13: 253540 | H13: 0 | I13: 0 | J13: 14191 | K13: 127242 | L13: 31487 | M13: 90035 | CB13: 421521 | EQ13: 597855 | ER13: 977950 | ES13: 590736 | ET13: 494765 | EU13: 354214 | EV13: 385296 | EW13: 4164 | EX13: 720710 | EY13: 100322 | EZ13: 3677 | FA13: 40372 | FB13: 352 | FC13: 3308 | FD13: 216 | FE13: 166 | FF13: 2850 | FG13: 162899 | FH13: 110693 | FI13: 147929 | FJ13: 107359 | FK13: 0 | FL13: 1 | FM13: 6288 | FN13: 0 | FO13: 0 | FP13: 55447 | FQ13: 45623 | FR13: 0 | FS13: 5187792 | FT13: 2336309 | FU13: 0 | FV13: 0 | FW13: 0 | FX13: 0 | FY13: 0 | FZ13: 0 | GA13: 7708 | GB13: 1.1357953e+08
A14: no_pdede | C14: 0.996724 | D14: 50000003 | E14: 50164331 | F14: 135055 | G14: 253537 | H14: 0 | I14: 0 | J14: 14275 | K14: 127293 | L14: 31620 | M14: 89988 | CB14: 426578 | EQ14: 597892 | ER14: 974517 | ES14: 590747 | ET14: 494793 | EU14: 354197 | EV14: 385289 | EW14: 4164 | EX14: 718900 | EY14: 100285 | EZ14: 3594 | FA14: 43874 | FB14: 355 | FC14: 3308 | FD14: 209 | FE14: 169 | FF14: 4660 | FG14: 162784 | FH14: 112507 | FI14: 151287 | FJ14: 107340 | FK14: 0 | FL14: 0 | FM14: 6288 | FN14: 0 | FO14: 0 | FP14: 55447 | FQ14: 45605 | FR14: 0 | FS14: 5249400 | FT14: 1253 | FU14: 1151486 | FV14: 23 | FW14: 468 | FX14: 1151486 | FY14: 0 | FZ14: 468 | GA14: 7708 | GB14: 1.1372318e+08
A15: client_001 Total | C15: 6.102535 | D15: 300000018 | E15: 295061761 | F15: 797183 | G15: 1520836 | H15: 306468 | I15: 123900 | J15: 91003 | K15: 797342 | L15: 184287 | M15: 563294 | N15: 4319130 | O15: 0 | P15: 2796 | Q15: 1851171 | R15: 2958504 | S15: 2841966 | T15: 3362556 | U15: 2641125 | V15: 1871412 | W15: 914913 | X15: 565785 | Y15: 170532 | Z15: 90891 | AA15: 116172 | AB15: 294975 | AC15: 114738 | AD15: 51852 | AE15: 155931 | AF15: 200049 | AG15: 677643 | AH15: 658851 | AI15: 894120 | AJ15: 917343 | AK15: 134541 | AL15: 0 | AM15: 0 | AN15: 0 | AO15: 28077 | AP15: 0 | AQ15: 0 | AR15: 0 | AS15: 0 | AT15: 0 | AU15: 0 | AV15: 0 | AW15: 0 | AX15: 0 | AY15: 0 | AZ15: 0 | BA15: 0 | BB15: 0 | BC15: 0 | BD15: 0 | BE15: 0 | BF15: 0 | BG15: 0 | BH15: 0 | BI15: 0 | BJ15: 0 | BK15: 0 | BL15: 0 | BM15: 0 | BN15: 0 | BO15: 0 | BP15: 0 | BQ15: 0 | BR15: 0 | BS15: 0 | BT15: 0 | BU15: 0 | BV15: 0 | BW15: 0 | BX15: 0 | BY15: 0 | BZ15: 0 | CA15: 0 | CB15: 3173255 | CC15: 4319130 | CD15: 1518 | CE15: 1086879 | CF15: 1051086 | CG15: 2173725 | CH15: 3125628 | CI15: 3397929 | CJ15: 1527807 | CK15: 1149948 | CL15: 1162512 | CM15: 1462767 | CN15: 724179 | CO15: 288069 | CP15: 69369 | CQ15: 126387 | CR15: 206436 | CS15: 254031 | CT15: 204150 | CU15: 356502 | CV15: 204720 | CW15: 765684 | CX15: 610857 | CY15: 1517424 | CZ15: 20259 | DA15: 0 | DB15: 0 | DC15: 0 | DD15: 28077 | DE15: 0 | DF15: 0 | DG15: 0 | DH15: 0 | DI15: 0 | DJ15: 0 | DK15: 0 | DL15: 0 | DM15: 0 | DN15: 0 | DO15: 0 | DP15: 0 | DQ15: 0 | DR15: 0 | DS15: 0 | DT15: 0 | DU15: 0 | DV15: 0 | DW15: 0 | DX15: 0 | DY15: 0 | DZ15: 0 | EA15: 0 | EB15: 0 | EC15: 0 | ED15: 0 | EE15: 0 | EF15: 0 | EG15: 0 | EH15: 0 | EI15: 0 | EJ15: 0 | EK15: 0 | EL15: 0 | EM15: 0 | EN15: 0 | EO15: 0 | EP15: 0 | EQ15: 3476271 | ER15: 5668180 | ES15: 3472619 | ET15: 2955016 | EU15: 2125202 | EV15: 2311732 | EW15: 24982 | EX15: 4312150 | EY15: 712785 | EZ15: 105649 | FA15: 394805 | FB15: 37266 | FC15: 31195 | FD15: 3607 | FE15: 1058 | FF15: 29216 | FG15: 961416 | FH15: 938181 | FI15: 1273658 | FJ15: 896258 | FK15: 0 | FL15: 2 | FM15: 37728 | FN15: 0 | FO15: 0 | FP15: 332676 | FQ15: 525852 | FR15: 0 | FS15: 163431893 | FT15: 4677589 | FU15: 3449936 | FV15: 46 | FW15: 939 | FX15: 3449936 | FY15: 0 | FZ15: 939 | GA15: 46248 | GB15: 8.5997453e+08
A16: client_002
A17: no_BTBX | C17: 1.09062 | D17: 50000001 | E17: 45845366 | F17: 57344 | G17: 77916 | H17: 0 | I17: 0 | J17: 5286 | K17: 44126 | L17: 6343 | M17: 17040 | CB17: 399867 | EQ17: 650095 | ER17: 711853 | ES17: 1514313 | ET17: 620861 | EU17: 844560 | EV17: 3517 | EW17: 20381 | EX17: 1084033 | EY17: 61989 | EZ17: 2837 | FA17: 3427 | FB17: 1853 | FC17: 937 | FD17: 7573 | FE17: 7452 | FF17: 896 | FG17: 60956 | FH17: 269377 | FI17: 69534 | FJ17: 251947 | FK17: 0 | FL17: 0 | FM17: 53828 | FN17: 0 | FO17: 0 | FP17: 18261 | FQ17: 179858 | FR17: 0 | FS17: 4878624 | FT17: 18435 | FU17: 0 | FV17: 0 | FW17: 0 | FX17: 0 | FY17: 0 | FZ17: 0 | GA17: 16301 | GB17: 1.0780699e+08
A18: fdip_BTBX | C18: 1.17455 | D18: 50000001 | E18: 42569327 | F18: 55997 | G18: 77841 | H18: 242553 | I18: 165945 | J18: 23963 | K18: 117324 | L18: 5035 | M18: 22224 | N18: 2175330 | O18: 0 | P18: 23503 | Q18: 442197 | R18: 1236364 | S18: 640839 | T18: 1358948 | U18: 950109 | V18: 1063251 | W18: 586666 | X18: 333840 | Y18: 220335 | Z18: 190281 | AA18: 160408 | AB18: 149956 | AC18: 84757 | AD18: 58585 | AE18: 61388 | AF18: 355892 | AG18: 398065 | AH18: 337599 | AI18: 201544 | AJ18: 7066 | AK18: 0 | AL18: 0 | AM18: 0 | AN18: 0 | AO18: 0 | AP18: 0 | AQ18: 7683 | AR18: 0 | AS18: 0 | AT18: 0 | AU18: 0 | AV18: 0 | AW18: 0 | AX18: 0 | AY18: 0 | AZ18: 33301 | BA18: 0 | BB18: 0 | BC18: 0 | BD18: 0 | BE18: 0 | BF18: 0 | BG18: 0 | BH18: 0 | BI18: 0 | BJ18: 0 | BK18: 0 | BL18: 0 | BM18: 0 | BN18: 0 | BO18: 0 | BP18: 0 | BQ18: 0 | BR18: 0 | BS18: 0 | BT18: 0 | BU18: 0 | BV18: 0 | BW18: 0 | BX18: 0 | BY18: 0 | BZ18: 0 | CA18: 0 | CB18: 640415 | CC18: 2175330 | CD18: 23286 | CE18: 218024 | CF18: 406398 | CG18: 779867 | CH18: 693746 | CI18: 744149 | CJ18: 1629952 | CK18: 847196 | CL18: 548878 | CM18: 451140 | CN18: 443072 | CO18: 193491 | CP18: 157057 | CQ18: 62320 | CR18: 98281 | CS18: 204485 | CT18: 97711 | CU18: 282214 | CV18: 560954 | CW18: 405618 | CX18: 6160 | CY18: 0 | CZ18: 0 | DA18: 0 | DB18: 7594 | DC18: 0 | DD18: 0 | DE18: 7683 | DF18: 0 | DG18: 0 | DH18: 0 | DI18: 0 | DJ18: 0 | DK18: 0 | DL18: 0 | DM18: 0 | DN18: 33301 | DO18: 0 | DP18: 0 | DQ18: 0 | DR18: 0 | DS18: 0 | DT18: 0 | DU18: 0 | DV18: 0 | DW18: 0 | DX18: 0 | DY18: 0 | DZ18: 0 | EA18: 0 | EB18: 0 | EC18: 0 | ED18: 0 | EE18: 0 | EF18: 0 | EG18: 0 | EH18: 0 | EI18: 0 | EJ18: 0 | EK18: 0 | EL18: 0 | EM18: 0 | EN18: 0 | EO18: 0 | EP18: 0 | EQ18: 601863 | ER18: 700776 | ES18: 1426129 | ET18: 620804 | EU18: 844558 | EV18: 3517 | EW18: 20381 | EX18: 1078401 | EY18: 110221 | EZ18: 8181 | FA18: 94386 | FB18: 4807 | FC18: 993 | FD18: 7573 | FE18: 7452 | FF18: 6526 | FG18: 59242 | FH18: 364427 | FI18: 216746 | FJ18: 341034 | FK18: 0 | FL18: 0 | FM18: 53828 | FN18: 0 | FO18: 0 | FP18: 18261 | FQ18: 268945 | FR18: 0 | FS18: 49939146 | FT18: 18435 | FU18: 0 | FV18: 0 | FW18: 0 | FX18: 0 | FY18: 0 | FZ18: 0 | GA18: 16301 | GB18: 1.7290937e+08
A19: fdip_convBTB | C19: 1.16225 | D19: 50000001 | E19: 43020172 | F19: 56199 | G19: 77838 | H19: 256809 | I19: 192162 | J19: 30735 | K19: 148566 | L19: 5086 | M19: 25291 | N19: 2175330 | O19: 0 | P19: 23503 | Q19: 442197 | R19: 1236364 | S19: 640839 | T19: 1358948 | U19: 950109 | V19: 1063251 | W19: 586666 | X19: 333840 | Y19: 220335 | Z19: 190281 | AA19: 160408 | AB19: 149956 | AC19: 84757 | AD19: 58585 | AE19: 61388 | AF19: 355892 | AG19: 398065 | AH19: 337599 | AI19: 201544 | AJ19: 7066 | AK19: 0 | AL19: 0 | AM19: 0 | AN19: 0 | AO19: 0 | AP19: 0 | AQ19: 7683 | AR19: 0 | AS19: 0 | AT19: 0 | AU19: 0 | AV19: 0 | AW19: 0 | AX19: 0 | AY19: 0 | AZ19: 33301 | BA19: 0 | BB19: 0 | BC19: 0 | BD19: 0 | BE19: 0 | BF19: 0 | BG19: 0 | BH19: 0 | BI19: 0 | BJ19: 0 | BK19: 0 | BL19: 0 | BM19: 0 | BN19: 0 | BO19: 0 | BP19: 0 | BQ19: 0 | BR19: 0 | BS19: 0 | BT19: 0 | BU19: 0 | BV19: 0 | BW19: 0 | BX19: 0 | BY19: 0 | BZ19: 0 | CA19: 0 | CB19: 692079 | CC19: 2175330 | CD19: 23286 | CE19: 218024 | CF19: 406398 | CG19: 779867 | CH19: 693746 | CI19: 744149 | CJ19: 1629952 | CK19: 847196 | CL19: 548878 | CM19: 451140 | CN19: 443072 | CO19: 193491 | CP19: 157057 | CQ19: 62320 | CR19: 98281 | CS19: 204485 | CT19: 97711 | CU19: 282214 | CV19: 560954 | CW19: 405618 | CX19: 6160 | CY19: 0 | CZ19: 0 | DA19: 0 | DB19: 7594 | DC19: 0 | DD19: 0 | DE19: 7683 | DF19: 0 | DG19: 0 | DH19: 0 | DI19: 0 | DJ19: 0 | DK19: 0 | DL19: 0 | DM19: 0 | DN19: 33301 | DO19: 0 | DP19: 0 | DQ19: 0 | DR19: 0 | DS19: 0 | DT19: 0 | DU19: 0 | DV19: 0 | DW19: 0 | DX19: 0 | DY19: 0 | DZ19: 0 | EA19: 0 | EB19: 0 | EC19: 0 | ED19: 0 | EE19: 0 | EF19: 0 | EG19: 0 | EH19: 0 | EI19: 0 | EJ19: 0 | EK19: 0 | EL19: 0 | EM19: 0 | EN19: 0 | EO19: 0 | EP19: 0 | EQ19: 589441 | ER19: 693823 | ES19: 1413200 | ET19: 616341 | EU19: 838592 | EV19: 3473 | EW19: 20552 | EX19: 1070663 | EY19: 122643 | EZ19: 11284 | FA19: 104390 | FB19: 11582 | FC19: 4254 | FD19: 13803 | FE19: 8263 | FF19: 14264 | FG19: 57301 | FH19: 390243 | FI19: 244535 | FJ19: 344295 | FK19: 0 | FL19: 0 | FM19: 53736 | FN19: 0 | FO19: 0 | FP19: 18172 | FQ19: 272387 | FR19: 0 | FS19: 54925547 | FT19: 2498619 | FU19: 0 | FV19: 0 | FW19: 0 | FX19: 0 | FY19: 0 | FZ19: 0 | GA19: 16301 | GB19: 1.8101846e+08
A20: fdip_pdede | C20: 1.17289 | D20: 50000001 | E20: 42629795 | F20: 55925 | G20: 77831 | H20: 226801 | I20: 160569 | J20: 22820 | K20: 117014 | L20: 5197 | M20: 22834 | N20: 2175330 | O20: 0 | P20: 23503 | Q20: 442197 | R20: 1236364 | S20: 640839 | T20: 1358948 | U20: 950109 | V20: 1063251 | W20: 586666 | X20: 333840 | Y20: 220335 | Z20: 190281 | AA20: 160408 | AB20: 149956 | AC20: 84757 | AD20: 58585 | AE20: 61388 | AF20: 355892 | AG20: 398065 | AH20: 337599 | AI20: 201544 | AJ20: 7066 | AK20: 0 | AL20: 0 | AM20: 0 | AN20: 0 | AO20: 0 | AP20: 0 | AQ20: 7683 | AR20: 0 | AS20: 0 | AT20: 0 | AU20: 0 | AV20: 0 | AW20: 0 | AX20: 0 | AY20: 0 | AZ20: 33301 | BA20: 0 | BB20: 0 | BC20: 0 | BD20: 0 | BE20: 0 | BF20: 0 | BG20: 0 | BH20: 0 | BI20: 0 | BJ20: 0 | BK20: 0 | BL20: 0 | BM20: 0 | BN20: 0 | BO20: 0 | BP20: 0 | BQ20: 0 | BR20: 0 | BS20: 0 | BT20: 0 | BU20: 0 | BV20: 0 | BW20: 0 | BX20: 0 | BY20: 0 | BZ20: 0 | CA20: 0 | CB20: 631081 | CC20: 2175330 | CD20: 23286 | CE20: 218024 | CF20: 406398 | CG20: 779867 | CH20: 693746 | CI20: 744149 | CJ20: 1629952 | CK20: 847196 | CL20: 548878 | CM20: 451140 | CN20: 443072 | CO20: 193491 | CP20: 157057 | CQ20: 62320 | CR20: 98281 | CS20: 204485 | CT20: 97711 | CU20: 282214 | CV20: 560954 | CW20: 405618 | CX20: 6160 | CY20: 0 | CZ20: 0 | DA20: 0 | DB20: 7594 | DC20: 0 | DD20: 0 | DE20: 7683 | DF20: 0 | DG20: 0 | DH20: 0 | DI20: 0 | DJ20: 0 | DK20: 0 | DL20: 0 | DM20: 0 | DN20: 33301 | DO20: 0 | DP20: 0 | DQ20: 0 | DR20: 0 | DS20: 0 | DT20: 0 | DU20: 0 | DV20: 0 | DW20: 0 | DX20: 0 | DY20: 0 | DZ20: 0 | EA20: 0 | EB20: 0 | EC20: 0 | ED20: 0 | EE20: 0 | EF20: 0 | EG20: 0 | EH20: 0 | EI20: 0 | EJ20: 0 | EK20: 0 | EL20: 0 | EM20: 0 | EN20: 0 | EO20: 0 | EP20: 0 | EQ20: 602262 | ER20: 700469 | ES20: 1425454 | ET20: 621070 | EU20: 848715 | EV20: 3611 | EW20: 20633 | EX20: 1082636 | EY20: 109822 | EZ20: 8274 | FA20: 94912 | FB20: 5170 | FC20: 1230 | FD20: 4945 | FE20: 5074 | FF20: 2291 | FG20: 59224 | FH20: 354431 | FI20: 217426 | FJ20: 340139 | FK20: 0 | FL20: 0 | FM20: 53831 | FN20: 0 | FO20: 0 | FP20: 18392 | FQ20: 267916 | FR20: 0 | FS20: 45947456 | FT20: 16589 | FU20: 2370521 | FV20: 91 | FW20: 10631 | FX20: 2370521 | FY20: 0 | FZ20: 10631 | GA20: 16301 | GB20: 1.7369635e+08
A21: no_convBTB | C21: 1.07453 | D21: 50000001 | E21: 46531898 | F21: 57475 | G21: 77921 | H21: 0 | I21: 0 | J21: 5327 | K21: 44151 | L21: 6403 | M21: 17039 | CB21: 444176 | EQ21: 638784 | ER21: 706146 | ES21: 1504138 | ET21: 616335 | EU21: 838594 | EV21: 3473 | EW21: 20552 | EX21: 1076204 | EY21: 73300 | EZ21: 5731 | FA21: 10442 | FB21: 7826 | FC21: 4261 | FD21: 13803 | FE21: 8263 | FF21: 8725 | FG21: 59642 | FH21: 292226 | FI21: 92308 | FJ21: 252183 | FK21: 0 | FL21: 0 | FM21: 53736 | FN21: 0 | FO21: 0 | FP21: 18172 | FQ21: 180275 | FR21: 0 | FS21: 5416272 | FT21: 2498621 | FU21: 0 | FV21: 0 | FW21: 0 | FX21: 0 | FY21: 0 | FZ21: 0 | GA21: 16301 | GB21: 1.1160071e+08
A22: no_pdede | C22: 1.08781 | D22: 50000001 | E22: 45963782 | F22: 57312 | G22: 77899 | H22: 0 | I22: 0 | J22: 5292 | K22: 44135 | L22: 6350 | M22: 17017 | CB22: 395286 | EQ22: 650473 | ER22: 711231 | ES22: 1513558 | ET22: 621095 | EU22: 848552 | EV22: 3607 | EW22: 20633 | EX22: 1083360 | EY22: 61611 | EZ22: 3208 | FA22: 4020 | FB22: 2265 | FC22: 1188 | FD22: 5063 | FE22: 5143 | FF22: 1569 | FG22: 60936 | FH22: 263940 | FI22: 70410 | FJ22: 250283 | FK22: 0 | FL22: 0 | FM22: 53831 | FN22: 0 | FO22: 0 | FP22: 18371 | FQ22: 178081 | FR22: 0 | FS22: 4823673 | FT22: 16931 | FU22: 1439135 | FV22: 91 | FW22: 10816 | FX22: 1439135 | FY22: 0 | FZ22: 10816 | GA22: 16301 | GB22: 1.107564e+08
A23: client_002 Total | C23: 6.76265 | D23: 300000006 | E23: 266560340 | F23: 340252 | G23: 467246 | H23: 726163 | I23: 518676 | J23: 93423 | K23: 515316 | L23: 34414 | M23: 121445 | N23: 6525990 | O23: 0 | P23: 70509 | Q23: 1326591 | R23: 3709092 | S23: 1922517 | T23: 4076844 | U23: 2850327 | V23: 3189753 | W23: 1759998 | X23: 1001520 | Y23: 661005 | Z23: 570843 | AA23: 481224 | AB23: 449868 | AC23: 254271 | AD23: 175755 | AE23: 184164 | AF23: 1067676 | AG23: 1194195 | AH23: 1012797 | AI23: 604632 | AJ23: 21198 | AK23: 0 | AL23: 0 | AM23: 0 | AN23: 0 | AO23: 0 | AP23: 0 | AQ23: 23049 | AR23: 0 | AS23: 0 | AT23: 0 | AU23: 0 | AV23: 0 | AW23: 0 | AX23: 0 | AY23: 0 | AZ23: 99903 | BA23: 0 | BB23: 0 | BC23: 0 | BD23: 0 | BE23: 0 | BF23: 0 | BG23: 0 | BH23: 0 | BI23: 0 | BJ23: 0 | BK23: 0 | BL23: 0 | BM23: 0 | BN23: 0 | BO23: 0 | BP23: 0 | BQ23: 0 | BR23: 0 | BS23: 0 | BT23: 0 | BU23: 0 | BV23: 0 | BW23: 0 | BX23: 0 | BY23: 0 | BZ23: 0 | CA23: 0 | CB23: 3202904 | CC23: 6525990 | CD23: 69858 | CE23: 654072 | CF23: 1219194 | CG23: 2339601 | CH23: 2081238 | CI23: 2232447 | CJ23: 4889856 | CK23: 2541588 | CL23: 1646634 | CM23: 1353420 | CN23: 1329216 | CO23: 580473 | CP23: 471171 | CQ23: 186960 | CR23: 294843 | CS23: 613455 | CT23: 293133 | CU23: 846642 | CV23: 1682862 | CW23: 1216854 | CX23: 18480 | CY23: 0 | CZ23: 0 | DA23: 0 | DB23: 22782 | DC23: 0 | DD23: 0 | DE23: 23049 | DF23: 0 | DG23: 0 | DH23: 0 | DI23: 0 | DJ23: 0 | DK23: 0 | DL23: 0 | DM23: 0 | DN23: 99903 | DO23: 0 | DP23: 0 | DQ23: 0 | DR23: 0 | DS23: 0 | DT23: 0 | DU23: 0 | DV23: 0 | DW23: 0 | DX23: 0 | DY23: 0 | DZ23: 0 | EA23: 0 | EB23: 0 | EC23: 0 | ED23: 0 | EE23: 0 | EF23: 0 | EG23: 0 | EH23: 0 | EI23: 0 | EJ23: 0 | EK23: 0 | EL23: 0 | EM23: 0 | EN23: 0 | EO23: 0 | EP23: 0 | EQ23: 3732918 | ER23: 4224298 | ES23: 8796792 | ET23: 3716506 | EU23: 5063571 | EV23: 21198 | EW23: 123132 | EX23: 6475297 | EY23: 539586 | EZ23: 39515 | FA23: 311577 | FB23: 33503 | FC23: 12863 | FD23: 52760 | FE23: 41647 | FF23: 34271 | FG23: 357301 | FH23: 1934644 | FI23: 910959 | FJ23: 1779881 | FK23: 0 | FL23: 0 | FM23: 322790 | FN23: 0 | FO23: 0 | FP23: 109629 | FQ23: 1347462 | FR23: 0 | FS23: 165930718 | FT23: 5067630 | FU23: 3809656 | FV23: 182 | FW23: 21447 | FX23: 3809656 | FY23: 0 | FZ23: 21447 | GA23: 97806 | GB23: 8.5778828e+08
A24: client_003
A25: no_BTBX | C25: 0.89626 | D25: 50000001 | E25: 55787366 | F25: 79604 | G25: 68166 | H25: 0 | I25: 0 | J25: 5794 | K25: 93958 | L25: 13238 | M25: 77714 | CB25: 527645 | EQ25: 1358076 | ER25: 484310 | ES25: 2020141 | ET25: 554292 | EU25: 644425 | EV25: 19681 | EW25: 11489 | EX25: 824154 | EY25: 175334 | EZ25: 3011 | FA25: 3361 | FB25: 1591 | FC25: 1110 | FD25: 7531 | FE25: 2451 | FF25: 1198 | FG25: 91563 | FH25: 253185 | FI25: 182897 | FJ25: 240493 | FK25: 0 | FL25: 0 | FM25: 43167 | FN25: 0 | FO25: 0 | FP25: 15329 | FQ25: 181997 | FR25: 0 | FS25: 6614268 | FT25: 15893 | FU25: 0 | FV25: 0 | FW25: 0 | FX25: 0 | FY25: 0 | FZ25: 0 | GA25: 25840 | GB25: 1.2043027e+08
A26: fdip_BTBX | C26: 0.911608 | D26: 50000001 | E26: 54848157 | F26: 78623 | G26: 67880 | H26: 232519 | I26: 172034 | J26: 17491 | K26: 147238 | L26: 9199 | M26: 98041 | N26: 1983451 | O26: 0 | P26: 16224 | Q26: 691304 | R26: 1635363 | S26: 771098 | T26: 2103487 | U26: 735227 | V26: 748884 | W26: 545310 | X26: 519294 | Y26: 222512 | Z26: 130884 | AA26: 175720 | AB26: 159194 | AC26: 127277 | AD26: 78864 | AE26: 69170 | AF26: 255696 | AG26: 219760 | AH26: 409829 | AI26: 140098 | AJ26: 8 | AK26: 0 | AL26: 0 | AM26: 0 | AN26: 0 | AO26: 0 | AP26: 0 | AQ26: 0 | AR26: 7797 | AS26: 0 | AT26: 0 | AU26: 0 | AV26: 0 | AW26: 0 | AX26: 0 | AY26: 0 | AZ26: 18615 | BA26: 0 | BB26: 0 | BC26: 0 | BD26: 0 | BE26: 0 | BF26: 0 | BG26: 0 | BH26: 0 | BI26: 0 | BJ26: 0 | BK26: 0 | BL26: 0 | BM26: 0 | BN26: 0 | BO26: 0 | BP26: 0 | BQ26: 0 | BR26: 0 | BS26: 0 | BT26: 0 | BU26: 0 | BV26: 0 | BW26: 0 | BX26: 0 | BY26: 0 | BZ26: 0 | CA26: 0 | CB26: 1380760 | CC26: 1983451 | CD26: 15376 | CE26: 290330 | CF26: 440239 | CG26: 1671126 | CH26: 523206 | CI26: 615310 | CJ26: 1079048 | CK26: 1708111 | CL26: 513556 | CM26: 590378 | CN26: 384404 | CO26: 144235 | CP26: 162616 | CQ26: 100562 | CR26: 67262 | CS26: 341296 | CT26: 103028 | CU26: 186774 | CV26: 505277 | CW26: 283199 | CX26: 29870 | CY26: 0 | CZ26: 0 | DA26: 0 | DB26: 0 | DC26: 0 | DD26: 0 | DE26: 0 | DF26: 7797 | DG26: 0 | DH26: 0 | DI26: 0 | DJ26: 0 | DK26: 0 | DL26: 0 | DM26: 0 | DN26: 18615 | DO26: 0 | DP26: 0 | DQ26: 0 | DR26: 0 | DS26: 0 | DT26: 0 | DU26: 0 | DV26: 0 | DW26: 0 | DX26: 0 | DY26: 0 | DZ26: 0 | EA26: 0 | EB26: 0 | EC26: 0 | ED26: 0 | EE26: 0 | EF26: 0 | EG26: 0 | EH26: 0 | EI26: 0 | EJ26: 0 | EK26: 0 | EL26: 0 | EM26: 0 | EN26: 0 | EO26: 0 | EP26: 0 | EQ26: 981829 | ER26: 477134 | ES26: 1642797 | ET26: 525505 | EU26: 644150 | EV26: 19681 | EW26: 11489 | EX26: 822069 | EY26: 551580 | EZ26: 5182 | FA26: 17168 | FB26: 370139 | FC26: 29896 | FD26: 7755 | FE26: 2500 | FF26: 3282 | FG26: 88872 | FH26: 319934 | FI26: 971954 | FJ26: 304384 | FK26: 0 | FL26: 0 | FM26: 43167 | FN26: 0 | FO26: 0 | FP26: 15328 | FQ26: 245889 | FR26: 0 | FS26: 110215766 | FT26: 15893 | FU26: 0 | FV26: 0 | FW26: 0 | FX26: 0 | FY26: 0 | FZ26: 0 | GA26: 25840 | GB26: 2.4894126e+08
A27: fdip_convBTB | C27: 0.907306 | D27: 50000001 | E27: 55108194 | F27: 78801 | G27: 67868 | H27: 235964 | I27: 186808 | J27: 19259 | K27: 159362 | L27: 9393 | M27: 105729 | N27: 1983451 | O27: 0 | P27: 16224 | Q27: 691304 | R27: 1635363 | S27: 771098 | T27: 2103487 | U27: 735227 | V27: 748884 | W27: 545310 | X27: 519294 | Y27: 222512 | Z27: 130884 | AA27: 175720 | AB27: 159194 | AC27: 127277 | AD27: 78864 | AE27: 69170 | AF27: 255696 | AG27: 219760 | AH27: 409829 | AI27: 140098 | AJ27: 8 | AK27: 0 | AL27: 0 | AM27: 0 | AN27: 0 | AO27: 0 | AP27: 0 | AQ27: 0 | AR27: 7797 | AS27: 0 | AT27: 0 | AU27: 0 | AV27: 0 | AW27: 0 | AX27: 0 | AY27: 0 | AZ27: 18615 | BA27: 0 | BB27: 0 | BC27: 0 | BD27: 0 | BE27: 0 | BF27: 0 | BG27: 0 | BH27: 0 | BI27: 0 | BJ27: 0 | BK27: 0 | BL27: 0 | BM27: 0 | BN27: 0 | BO27: 0 | BP27: 0 | BQ27: 0 | BR27: 0 | BS27: 0 | BT27: 0 | BU27: 0 | BV27: 0 | BW27: 0 | BX27: 0 | BY27: 0 | BZ27: 0 | CA27: 0 | CB27: 1395465 | CC27: 1983451 | CD27: 15376 | CE27: 290330 | CF27: 440239 | CG27: 1671126 | CH27: 523206 | CI27: 615310 | CJ27: 1079048 | CK27: 1708111 | CL27: 513556 | CM27: 590378 | CN27: 384404 | CO27: 144235 | CP27: 162616 | CQ27: 100562 | CR27: 67262 | CS27: 341296 | CT27: 103028 | CU27: 186774 | CV27: 505277 | CW27: 283199 | CX27: 29870 | CY27: 0 | CZ27: 0 | DA27: 0 | DB27: 0 | DC27: 0 | DD27: 0 | DE27: 0 | DF27: 7797 | DG27: 0 | DH27: 0 | DI27: 0 | DJ27: 0 | DK27: 0 | DL27: 0 | DM27: 0 | DN27: 18615 | DO27: 0 | DP27: 0 | DQ27: 0 | DR27: 0 | DS27: 0 | DT27: 0 | DU27: 0 | DV27: 0 | DW27: 0 | DX27: 0 | DY27: 0 | DZ27: 0 | EA27: 0 | EB27: 0 | EC27: 0 | ED27: 0 | EE27: 0 | EF27: 0 | EG27: 0 | EH27: 0 | EI27: 0 | EJ27: 0 | EK27: 0 | EL27: 0 | EM27: 0 | EN27: 0 | EO27: 0 | EP27: 0 | EQ27: 978500 | ER27: 472618 | ES27: 1638342 | ET27: 523970 | EU27: 642436 | EV27: 19680 | EW27: 11551 | EX27: 818086 | EY27: 554909 | EZ27: 7282 | FA27: 21302 | FB27: 372876 | FC27: 31092 | FD27: 9510 | FE27: 2737 | FF27: 7265 | FG27: 84283 | FH27: 328622 | FI27: 982560 | FJ27: 304207 | FK27: 0 | FL27: 0 | FM27: 43155 | FN27: 0 | FO27: 0 | FP27: 15257 | FQ27: 245795 | FR27: 0 | FS27: 112273360 | FT27: 2307546 | FU27: 0 | FV27: 0 | FW27: 0 | FX27: 0 | FY27: 0 | FZ27: 0 | GA27: 25840 | GB27: 2.5361976e+08
A28: fdip_pdede | C28: 0.909694 | D28: 50000001 | E28: 54963539 | F28: 78718 | G28: 67889 | H28: 224190 | I28: 169994 | J28: 17616 | K28: 148485 | L28: 9429 | M28: 99360 | N28: 1983451 | O28: 0 | P28: 16224 | Q28: 691304 | R28: 1635363 | S28: 771097 | T28: 2103487 | U28: 735227 | V28: 748882 | W28: 545307 | X28: 519294 | Y28: 222512 | Z28: 130884 | AA28: 175720 | AB28: 159194 | AC28: 127277 | AD28: 78864 | AE28: 69170 | AF28: 255696 | AG28: 219760 | AH28: 409829 | AI28: 140098 | AJ28: 8 | AK28: 0 | AL28: 0 | AM28: 0 | AN28: 0 | AO28: 0 | AP28: 0 | AQ28: 0 | AR28: 7797 | AS28: 0 | AT28: 0 | AU28: 0 | AV28: 0 | AW28: 0 | AX28: 0 | AY28: 0 | AZ28: 18615 | BA28: 0 | BB28: 0 | BC28: 0 | BD28: 0 | BE28: 0 | BF28: 0 | BG28: 0 | BH28: 0 | BI28: 0 | BJ28: 0 | BK28: 0 | BL28: 0 | BM28: 0 | BN28: 0 | BO28: 0 | BP28: 0 | BQ28: 0 | BR28: 0 | BS28: 0 | BT28: 0 | BU28: 0 | BV28: 0 | BW28: 0 | BX28: 0 | BY28: 0 | BZ28: 0 | CA28: 0 | CB28: 1376418 | CC28: 1983451 | CD28: 15376 | CE28: 290330 | CF28: 440239 | CG28: 1671125 | CH28: 523206 | CI28: 615310 | CJ28: 1079047 | CK28: 1708110 | CL28: 513553 | CM28: 590378 | CN28: 384404 | CO28: 144235 | CP28: 162616 | CQ28: 100562 | CR28: 67262 | CS28: 341296 | CT28: 103028 | CU28: 186774 | CV28: 505277 | CW28: 283199 | CX28: 29870 | CY28: 0 | CZ28: 0 | DA28: 0 | DB28: 0 | DC28: 0 | DD28: 0 | DE28: 0 | DF28: 7797 | DG28: 0 | DH28: 0 | DI28: 0 | DJ28: 0 | DK28: 0 | DL28: 0 | DM28: 0 | DN28: 18615 | DO28: 0 | DP28: 0 | DQ28: 0 | DR28: 0 | DS28: 0 | DT28: 0 | DU28: 0 | DV28: 0 | DW28: 0 | DX28: 0 | DY28: 0 | DZ28: 0 | EA28: 0 | EB28: 0 | EC28: 0 | ED28: 0 | EE28: 0 | EF28: 0 | EG28: 0 | EH28: 0 | EI28: 0 | EJ28: 0 | EK28: 0 | EL28: 0 | EM28: 0 | EN28: 0 | EO28: 0 | EP28: 0 | EQ28: 981718 | ER28: 476657 | ES28: 1642374 | ET28: 525793 | EU28: 646477 | EV28: 19724 | EW28: 11567 | EX28: 822794 | EY28: 551690 | EZ28: 5474 | FA28: 17572 | FB28: 370338 | FC28: 29918 | FD28: 5936 | FE28: 1561 | FF28: 2557 | FG28: 88630 | FH28: 315047 | FI28: 972741 | FJ28: 302740 | FK28: 0 | FL28: 0 | FM28: 43176 | FN28: 0 | FO28: 0 | FP28: 15404 | FQ28: 244160 | FR28: 0 | FS28: 106604173 | FT28: 16374 | FU28: 2098323 | FV28: 130 | FW28: 8023 | FX28: 2098323 | FY28: 0 | FZ28: 8023 | GA28: 25840 | GB28: 2.4963902e+08
A29: no_convBTB | C29: 0.89244 | D29: 50000001 | E29: 56026197 | F29: 79628 | G29: 68175 | H29: 0 | I29: 0 | J29: 5794 | K29: 93920 | L29: 13366 | M29: 77644 | CB29: 539354 | EQ29: 1354996 | ER29: 481267 | ES29: 2016025 | ET29: 552767 | EU29: 642715 | EV29: 19680 | EW29: 11551 | EX29: 820158 | EY29: 178414 | EZ29: 4673 | FA29: 6442 | FB29: 4007 | FC29: 2296 | FD29: 9282 | FE29: 2688 | FF29: 5194 | FG29: 87943 | FH29: 259983 | FI29: 191428 | FJ29: 238413 | FK29: 0 | FL29: 0 | FM29: 43155 | FN29: 0 | FO29: 0 | FP29: 15258 | FQ29: 180000 | FR29: 0 | FS29: 6778644 | FT29: 2307549 | FU29: 0 | FV29: 0 | FW29: 0 | FX29: 0 | FY29: 0 | FZ29: 0 | GA29: 25840 | GB29: 1.2314445e+08
A30: no_pdede | C30: 0.894132 | D30: 50000001 | E30: 55920171 | F30: 79641 | G30: 68173 | H30: 0 | I30: 0 | J30: 5763 | K30: 94015 | L30: 13289 | M30: 77671 | CB30: 525802 | EQ30: 1358753 | ER30: 483719 | ES30: 2019718 | ET30: 554579 | EU30: 646542 | EV30: 19722 | EW30: 11567 | EX30: 823063 | EY30: 174657 | EZ30: 3395 | FA30: 3802 | FB30: 1780 | FC30: 1144 | FD30: 5878 | FE30: 1547 | FF30: 2289 | FG30: 91298 | FH30: 251732 | FI30: 182772 | FJ30: 240010 | FK30: 0 | FL30: 0 | FM30: 43175 | FN30: 0 | FO30: 0 | FP30: 15410 | FQ30: 181425 | FR30: 0 | FS30: 6593229 | FT30: 16273 | FU30: 1169211 | FV30: 130 | FW30: 7954 | FX30: 1169211 | FY30: 0 | FZ30: 7954 | GA30: 25840 | GB30: 1.2289231e+08
A31: client_003 Total | C31: 5.41144 | D31: 300000006 | E31: 332653624 | F31: 475015 | G31: 408151 | H31: 692673 | I31: 528836 | J31: 71717 | K31: 736978 | L31: 67914 | M31: 536159 | N31: 5950353 | O31: 0 | P31: 48672 | Q31: 2073912 | R31: 4906089 | S31: 2313293 | T31: 6310461 | U31: 2205681 | V31: 2246650 | W31: 1635927 | X31: 1557882 | Y31: 667536 | Z31: 392652 | AA31: 527160 | AB31: 477582 | AC31: 381831 | AD31: 236592 | AE31: 207510 | AF31: 767088 | AG31: 659280 | AH31: 1229487 | AI31: 420294 | AJ31: 24 | AK31: 0 | AL31: 0 | AM31: 0 | AN31: 0 | AO31: 0 | AP31: 0 | AQ31: 0 | AR31: 23391 | AS31: 0 | AT31: 0 | AU31: 0 | AV31: 0 | AW31: 0 | AX31: 0 | AY31: 0 | AZ31: 55845 | BA31: 0 | BB31: 0 | BC31: 0 | BD31: 0 | BE31: 0 | BF31: 0 | BG31: 0 | BH31: 0 | BI31: 0 | BJ31: 0 | BK31: 0 | BL31: 0 | BM31: 0 | BN31: 0 | BO31: 0 | BP31: 0 | BQ31: 0 | BR31: 0 | BS31: 0 | BT31: 0 | BU31: 0 | BV31: 0 | BW31: 0 | BX31: 0 | BY31: 0 | BZ31: 0 | CA31: 0 | CB31: 5745444 | CC31: 5950353 | CD31: 46128 | CE31: 870990 | CF31: 1320717 | CG31: 5013377 | CH31: 1569618 | CI31: 1845930 | CJ31: 3237143 | CK31: 5124332 | CL31: 1540665 | CM31: 1771134 | CN31: 1153212 | CO31: 432705 | CP31: 487848 | CQ31: 301686 | CR31: 201786 | CS31: 1023888 | CT31: 309084 | CU31: 560322 | CV31: 1515831 | CW31: 849597 | CX31: 89610 | CY31: 0 | CZ31: 0 | DA31: 0 | DB31: 0 | DC31: 0 | DD31: 0 | DE31: 0 | DF31: 23391 | DG31: 0 | DH31: 0 | DI31: 0 | DJ31: 0 | DK31: 0 | DL31: 0 | DM31: 0 | DN31: 55845 | DO31: 0 | DP31: 0 | DQ31: 0 | DR31: 0 | DS31: 0 | DT31: 0 | DU31: 0 | DV31: 0 | DW31: 0 | DX31: 0 | DY31: 0 | DZ31: 0 | EA31: 0 | EB31: 0 | EC31: 0 | ED31: 0 | EE31: 0 | EF31: 0 | EG31: 0 | EH31: 0 | EI31: 0 | EJ31: 0 | EK31: 0 | EL31: 0 | EM31: 0 | EN31: 0 | EO31: 0 | EP31: 0 | EQ31: 7013872 | ER31: 2875705 | ES31: 10979397 | ET31: 3236906 | EU31: 3866745 | EV31: 118168 | EW31: 69214 | EX31: 4930324 | EY31: 2186584 | EZ31: 29017 | FA31: 69647 | FB31: 1120731 | FC31: 95456 | FD31: 45892 | FE31: 13484 | FF31: 21785 | FG31: 532589 | FH31: 1728503 | FI31: 3484352 | FJ31: 1630247 | FK31: 0 | FL31: 0 | FM31: 258995 | FN31: 0 | FO31: 0 | FP31: 91986 | FQ31: 1279266 | FR31: 0 | FS31: 349079440 | FT31: 4679528 | FU31: 3267534 | FV31: 260 | FW31: 15977 | FX31: 3267534 | FY31: 0 | FZ31: 15977 | GA31: 155040 | GB31: 1.1186671e+09
A32: client_004
A33: no_BTBX | C33: 0.847683 | D33: 50000001 | E33: 58984307 | F33: 141348 | G33: 238860 | H33: 0 | I33: 0 | J33: 15773 | K33: 38081 | L33: 28666 | M33: 36822 | CB33: 973129 | EQ33: 789748 | ER33: 1101438 | ES33: 1297711 | ET33: 443203 | EU33: 542789 | EV33: 443407 | EW33: 3952 | EX33: 1011915 | EY33: 107672 | EZ33: 25841 | FA33: 25958 | FB33: 16411 | FC33: 6543 | FD33: 19542 | FE33: 17474 | FF33: 6801 | FG33: 362971 | FH33: 436195 | FI33: 173963 | FJ33: 383916 | FK33: 0 | FL33: 2 | FM33: 88694 | FN33: 0 | FO33: 17 | FP33: 146175 | FQ33: 149028 | FR33: 0 | FS33: 13169087 | FT33: 71179 | FU33: 0 | FV33: 0 | FW33: 0 | FX33: 0 | FY33: 0 | FZ33: 0 | GA33: 47673 | GB33: 1.3134629e+08
A34: fdip_BTBX | C34: 0.953559 | D34: 50000001 | E34: 52435168 | F34: 137597 | G34: 238591 | H34: 334158 | I34: 169895 | J34: 35516 | K34: 173438 | L34: 16659 | M34: 83605 | N34: 1782349 | O34: 0 | P34: 23795 | Q34: 465039 | R34: 1286683 | S34: 1474449 | T34: 1354971 | U34: 930720 | V34: 776738 | W34: 437224 | X34: 246056 | Y34: 166029 | Z34: 154169 | AA34: 192703 | AB34: 218280 | AC34: 364242 | AD34: 142151 | AE34: 77842 | AF34: 109825 | AG34: 131823 | AH34: 189269 | AI34: 243916 | AJ34: 444015 | AK34: 90615 | AL34: 16 | AM34: 0 | AN34: 0 | AO34: 11685 | AP34: 0 | AQ34: 0 | AR34: 0 | AS34: 0 | AT34: 0 | AU34: 0 | AV34: 0 | AW34: 0 | AX34: 0 | AY34: 0 | AZ34: 0 | BA34: 0 | BB34: 0 | BC34: 0 | BD34: 0 | BE34: 0 | BF34: 0 | BG34: 0 | BH34: 0 | BI34: 0 | BJ34: 0 | BK34: 0 | BL34: 0 | BM34: 0 | BN34: 0 | BO34: 0 | BP34: 0 | BQ34: 0 | BR34: 0 | BS34: 0 | BT34: 0 | BU34: 0 | BV34: 0 | BW34: 0 | BX34: 0 | BY34: 2 | BZ34: 0 | CA34: 0 | CB34: 1263226 | CC34: 1782349 | CD34: 14934 | CE34: 246842 | CF34: 495000 | CG34: 1073619 | CH34: 1018796 | CI34: 1065116 | CJ34: 1009883 | CK34: 754101 | CL34: 732197 | CM34: 352846 | CN34: 297061 | CO34: 200537 | CP34: 204780 | CQ34: 382148 | CR34: 232313 | CS34: 102729 | CT34: 108513 | CU34: 81831 | CV34: 174167 | CW34: 220162 | CX34: 71829 | CY34: 674821 | CZ34: 6345 | DA34: 0 | DB34: 0 | DC34: 0 | DD34: 11685 | DE34: 0 | DF34: 0 | DG34: 0 | DH34: 0 | DI34: 0 | DJ34: 0 | DK34: 0 | DL34: 0 | DM34: 0 | DN34: 0 | DO34: 0 | DP34: 0 | DQ34: 0 | DR34: 0 | DS34: 0 | DT34: 0 | DU34: 0 | DV34: 0 | DW34: 0 | DX34: 0 | DY34: 0 | DZ34: 0 | EA34: 0 | EB34: 0 | EC34: 0 | ED34: 0 | EE34: 0 | EF34: 0 | EG34: 0 | EH34: 0 | EI34: 0 | EJ34: 0 | EK34: 0 | EL34: 0 | EM34: 2 | EN34: 0 | EO34: 0 | EP34: 0 | EQ34: 733707 | ER34: 1019302 | ES34: 1263049 | ET34: 441023 | EU34: 542359 | EV34: 443409 | EW34: 3953 | EX34: 1007255 | EY34: 163719 | EZ34: 82842 | FA34: 78431 | FB34: 23743 | FC34: 7697 | FD34: 21005 | FE34: 17474 | FF34: 11469 | FG34: 354604 | FH34: 562610 | FI34: 346012 | FJ34: 502242 | FK34: 0 | FL34: 2 | FM34: 88694 | FN34: 0 | FO34: 17 | FP34: 146175 | FQ34: 267354 | FR34: 0 | FS34: 106376724 | FT34: 71179 | FU34: 0 | FV34: 0 | FW34: 0 | FX34: 0 | FY34: 0 | FZ34: 0 | GA34: 47673 | GB34: 2.4214079e+08
A35: fdip_convBTB | C35: 0.944769 | D35: 50000001 | E35: 52922970 | F35: 137600 | G35: 238606 | H35: 335938 | I35: 206721 | J35: 36718 | K35: 203013 | L35: 16423 | M35: 94252 | N35: 1782349 | O35: 0 | P35: 23795 | Q35: 465039 | R35: 1286683 | S35: 1474449 | T35: 1354971 | U35: 930720 | V35: 776738 | W35: 437224 | X35: 246056 | Y35: 166029 | Z35: 154169 | AA35: 192703 | AB35: 218280 | AC35: 364242 | AD35: 142151 | AE35: 77842 | AF35: 109825 | AG35: 131823 | AH35: 189269 | AI35: 243916 | AJ35: 444015 | AK35: 90615 | AL35: 16 | AM35: 0 | AN35: 0 | AO35: 11685 | AP35: 0 | AQ35: 0 | AR35: 0 | AS35: 0 | AT35: 0 | AU35: 0 | AV35: 0 | AW35: 0 | AX35: 0 | AY35: 0 | AZ35: 0 | BA35: 0 | BB35: 0 | BC35: 0 | BD35: 0 | BE35: 0 | BF35: 0 | BG35: 0 | BH35: 0 | BI35: 0 | BJ35: 0 | BK35: 0 | BL35: 0 | BM35: 0 | BN35: 0 | BO35: 0 | BP35: 0 | BQ35: 0 | BR35: 0 | BS35: 0 | BT35: 0 | BU35: 0 | BV35: 0 | BW35: 0 | BX35: 0 | BY35: 2 | BZ35: 0 | CA35: 0 | CB35: 1293305 | CC35: 1782349 | CD35: 14934 | CE35: 246842 | CF35: 495000 | CG35: 1073619 | CH35: 1018796 | CI35: 1065116 | CJ35: 1009883 | CK35: 754101 | CL35: 732197 | CM35: 352846 | CN35: 297061 | CO35: 200537 | CP35: 204780 | CQ35: 382148 | CR35: 232313 | CS35: 102729 | CT35: 108513 | CU35: 81831 | CV35: 174167 | CW35: 220162 | CX35: 71829 | CY35: 674821 | CZ35: 6345 | DA35: 0 | DB35: 0 | DC35: 0 | DD35: 11685 | DE35: 0 | DF35: 0 | DG35: 0 | DH35: 0 | DI35: 0 | DJ35: 0 | DK35: 0 | DL35: 0 | DM35: 0 | DN35: 0 | DO35: 0 | DP35: 0 | DQ35: 0 | DR35: 0 | DS35: 0 | DT35: 0 | DU35: 0 | DV35: 0 | DW35: 0 | DX35: 0 | DY35: 0 | DZ35: 0 | EA35: 0 | EB35: 0 | EC35: 0 | ED35: 0 | EE35: 0 | EF35: 0 | EG35: 0 | EH35: 0 | EI35: 0 | EJ35: 0 | EK35: 0 | EL35: 0 | EM35: 2 | EN35: 0 | EO35: 0 | EP35: 0 | EQ35: 724529 | ER35: 1005342 | ES35: 1249731 | ET35: 435925 | EU35: 538982 | EV35: 443689 | EW35: 3969 | EX35: 995501 | EY35: 172897 | EZ35: 90957 | FA35: 89702 | FB35: 31635 | FC35: 11962 | FD35: 25379 | FE35: 17014 | FF35: 23223 | FG35: 335229 | FH35: 579371 | FI35: 378705 | FJ35: 495307 | FK35: 0 | FL35: 2 | FM35: 88294 | FN35: 0 | FO35: 16 | FP35: 146151 | FQ35: 260844 | FR35: 0 | FS35: 109586374 | FT35: 2165606 | FU35: 0 | FV35: 0 | FW35: 0 | FX35: 0 | FY35: 0 | FZ35: 0 | GA35: 47673 | GB35: 2.4805877e+08
A36: fdip_pdede | C36: 0.950103 | D36: 50000001 | E36: 52625876 | F36: 137621 | G36: 238591 | H36: 322896 | I36: 177978 | J36: 35818 | K36: 177899 | L36: 17582 | M36: 86878 | N36: 1782349 | O36: 0 | P36: 23795 | Q36: 465039 | R36: 1286683 | S36: 1474449 | T36: 1354971 | U36: 930720 | V36: 776738 | W36: 437224 | X36: 246056 | Y36: 166029 | Z36: 154169 | AA36: 192703 | AB36: 218280 | AC36: 364242 | AD36: 142151 | AE36: 77842 | AF36: 109825 | AG36: 131823 | AH36: 189269 | AI36: 243916 | AJ36: 444015 | AK36: 90615 | AL36: 16 | AM36: 0 | AN36: 0 | AO36: 11685 | AP36: 0 | AQ36: 0 | AR36: 0 | AS36: 0 | AT36: 0 | AU36: 0 | AV36: 0 | AW36: 0 | AX36: 0 | AY36: 0 | AZ36: 0 | BA36: 0 | BB36: 0 | BC36: 0 | BD36: 0 | BE36: 0 | BF36: 0 | BG36: 0 | BH36: 0 | BI36: 0 | BJ36: 0 | BK36: 0 | BL36: 0 | BM36: 0 | BN36: 0 | BO36: 0 | BP36: 0 | BQ36: 0 | BR36: 0 | BS36: 0 | BT36: 0 | BU36: 0 | BV36: 0 | BW36: 0 | BX36: 0 | BY36: 2 | BZ36: 0 | CA36: 0 | CB36: 1252322 | CC36: 1782349 | CD36: 14934 | CE36: 246842 | CF36: 495000 | CG36: 1073619 | CH36: 1018796 | CI36: 1065116 | CJ36: 1009883 | CK36: 754101 | CL36: 732197 | CM36: 352846 | CN36: 297061 | CO36: 200537 | CP36: 204780 | CQ36: 382148 | CR36: 232313 | CS36: 102729 | CT36: 108513 | CU36: 81831 | CV36: 174167 | CW36: 220162 | CX36: 71829 | CY36: 674821 | CZ36: 6345 | DA36: 0 | DB36: 0 | DC36: 0 | DD36: 11685 | DE36: 0 | DF36: 0 | DG36: 0 | DH36: 0 | DI36: 0 | DJ36: 0 | DK36: 0 | DL36: 0 | DM36: 0 | DN36: 0 | DO36: 0 | DP36: 0 | DQ36: 0 | DR36: 0 | DS36: 0 | DT36: 0 | DU36: 0 | DV36: 0 | DW36: 0 | DX36: 0 | DY36: 0 | DZ36: 0 | EA36: 0 | EB36: 0 | EC36: 0 | ED36: 0 | EE36: 0 | EF36: 0 | EG36: 0 | EH36: 0 | EI36: 0 | EJ36: 0 | EK36: 0 | EL36: 0 | EM36: 2 | EN36: 0 | EO36: 0 | EP36: 0 | EQ36: 730971 | ER36: 1017448 | ES36: 1261700 | ET36: 443294 | EU36: 545810 | EV36: 447444 | EW36: 3983 | EX36: 1005387 | EY36: 166455 | EZ36: 83806 | FA36: 80113 | FB36: 24300 | FC36: 7639 | FD36: 16568 | FE36: 12182 | FF36: 13337 | FG36: 351430 | FH36: 552298 | FI36: 348594 | FJ36: 496492 | FK36: 0 | FL36: 2 | FM36: 88644 | FN36: 0 | FO36: 18 | FP36: 146395 | FQ36: 261433 | FR36: 0 | FS36: 97293884 | FT36: 75756 | FU36: 3650436 | FV36: 59 | FW36: 31503 | FX36: 3650436 | FY36: 0 | FZ36: 31503 | GA36: 47673 | GB36: 2.4058967e+08
A37: no_convBTB | C37: 0.838897 | D37: 50000001 | E37: 59602043 | F37: 141391 | G37: 238871 | H37: 0 | I37: 0 | J37: 15779 | K37: 38073 | L37: 28759 | M37: 36794 | CB37: 1002713 | EQ37: 779791 | ER37: 1091631 | ES37: 1286650 | ET37: 438997 | EU37: 539423 | EV37: 443687 | EW37: 3968 | EX37: 1000129 | EY37: 117629 | EZ37: 31221 | FA37: 34617 | FB37: 23240 | FC37: 10058 | FD37: 23763 | FE37: 17014 | FF37: 18587 | FG37: 348421 | FH37: 454169 | FI37: 200123 | FJ37: 378163 | FK37: 0 | FL37: 2 | FM37: 88294 | FN37: 0 | FO37: 16 | FP37: 146151 | FQ37: 143700 | FR37: 0 | FS37: 13625507 | FT37: 2165586 | FU37: 0 | FV37: 0 | FW37: 0 | FX37: 0 | FY37: 0 | FZ37: 0 | GA37: 47673 | GB37: 1.3456263e+08
A38: no_pdede | C38: 0.843375 | D38: 50000001 | E38: 59285594 | F38: 141439 | G38: 238857 | H38: 0 | I38: 0 | J38: 15783 | K38: 38368 | L38: 28836 | M38: 37416 | CB38: 970523 | EQ38: 786329 | ER38: 1099060 | ES38: 1296642 | ET38: 444318 | EU38: 545854 | EV38: 447431 | EW38: 3980 | EX38: 1006469 | EY38: 111091 | EZ38: 27155 | FA38: 27848 | FB38: 16654 | FC38: 6597 | FD38: 16551 | FE38: 12179 | FF38: 12247 | FG38: 359396 | FH38: 432447 | FI38: 178680 | FJ38: 380805 | FK38: 0 | FL38: 2 | FM38: 88648 | FN38: 0 | FO38: 18 | FP38: 146402 | FQ38: 145735 | FR38: 0 | FS38: 13161833 | FT38: 75701 | FU38: 1744839 | FV38: 59 | FW38: 31473 | FX38: 1744839 | FY38: 0 | FZ38: 31473 | GA38: 47673 | GB38: 1.3518725e+08
A39: client_004 Total | C39: 5.378386 | D39: 300000006 | E39: 335855958 | F39: 836996 | G39: 1432376 | H39: 992992 | I39: 554594 | J39: 155387 | K39: 668872 | L39: 136925 | M39: 375767 | N39: 5347047 | O39: 0 | P39: 71385 | Q39: 1395117 | R39: 3860049 | S39: 4423347 | T39: 4064913 | U39: 2792160 | V39: 2330214 | W39: 1311672 | X39: 738168 | Y39: 498087 | Z39: 462507 | AA39: 578109 | AB39: 654840 | AC39: 1092726 | AD39: 426453 | AE39: 233526 | AF39: 329475 | AG39: 395469 | AH39: 567807 | AI39: 731748 | AJ39: 1332045 | AK39: 271845 | AL39: 48 | AM39: 0 | AN39: 0 | AO39: 35055 | AP39: 0 | AQ39: 0 | AR39: 0 | AS39: 0 | AT39: 0 | AU39: 0 | AV39: 0 | AW39: 0 | AX39: 0 | AY39: 0 | AZ39: 0 | BA39: 0 | BB39: 0 | BC39: 0 | BD39: 0 | BE39: 0 | BF39: 0 | BG39: 0 | BH39: 0 | BI39: 0 | BJ39: 0 | BK39: 0 | BL39: 0 | BM39: 0 | BN39: 0 | BO39: 0 | BP39: 0 | BQ39: 0 | BR39: 0 | BS39: 0 | BT39: 0 | BU39: 0 | BV39: 0 | BW39: 0 | BX39: 0 | BY39: 6 | BZ39: 0 | CA39: 0 | CB39: 6755218 | CC39: 5347047 | CD39: 44802 | CE39: 740526 | CF39: 1485000 | CG39: 3220857 | CH39: 3056388 | CI39: 3195348 | CJ39: 3029649 | CK39: 2262303 | CL39: 2196591 | CM39: 1058538 | CN39: 891183 | CO39: 601611 | CP39: 614340 | CQ39: 1146444 | CR39: 696939 | CS39: 308187 | CT39: 325539 | CU39: 245493 | CV39: 522501 | CW39: 660486 | CX39: 215487 | CY39: 2024463 | CZ39: 19035 | DA39: 0 | DB39: 0 | DC39: 0 | DD39: 35055 | DE39: 0 | DF39: 0 | DG39: 0 | DH39: 0 | DI39: 0 | DJ39: 0 | DK39: 0 | DL39: 0 | DM39: 0 | DN39: 0 | DO39: 0 | DP39: 0 | DQ39: 0 | DR39: 0 | DS39: 0 | DT39: 0 | DU39: 0 | DV39: 0 | DW39: 0 | DX39: 0 | DY39: 0 | DZ39: 0 | EA39: 0 | EB39: 0 | EC39: 0 | ED39: 0 | EE39: 0 | EF39: 0 | EG39: 0 | EH39: 0 | EI39: 0 | EJ39: 0 | EK39: 0 | EL39: 0 | EM39: 6 | EN39: 0 | EO39: 0 | EP39: 0 | EQ39: 4545075 | ER39: 6334221 | ES39: 7655483 | ET39: 2646760 | EU39: 3255217 | EV39: 2669067 | EW39: 23805 | EX39: 6026656 | EY39: 839463 | EZ39: 341822 | FA39: 336669 | FB39: 135983 | FC39: 50496 | FD39: 122808 | FE39: 93337 | FF39: 85664 | FG39: 2112051 | FH39: 3017090 | FI39: 1626077 | FJ39: 2636925 | FK39: 0 | FL39: 12 | FM39: 531268 | FN39: 0 | FO39: 102 | FP39: 877449 | FQ39: 1228094 | FR39: 0 | FS39: 353213409 | FT39: 4625007 | FU39: 5395275 | FV39: 118 | FW39: 62976 | FX39: 5395275 | FY39: 0 | FZ39: 62976 | GA39: 286038 | GB39: 1.1318854e+09
A40: client_005
A41: no_BTBX | C41: 0.893434 | D41: 50000001 | E41: 55963827 | F41: 63422 | G41: 120310 | H41: 0 | I41: 0 | J41: 7110 | K41: 81612 | L41: 31979 | M41: 83743 | CB41: 548014 | EQ41: 747319 | ER41: 662653 | ES41: 1187616 | ET41: 678966 | EU41: 928539 | EV41: 20476 | EW41: 12755 | EX41: 1170337 | EY41: 98278 | EZ41: 3693 | FA41: 3970 | FB41: 2213 | FC41: 1473 | FD41: 8108 | FE41: 7595 | FF41: 1649 | FG41: 141831 | FH41: 298672 | FI41: 107511 | FJ41: 279204 | FK41: 0 | FL41: 0 | FM41: 39476 | FN41: 0 | FO41: 0 | FP41: 27993 | FQ41: 211735 | FR41: 0 | FS41: 6925524 | FT41: 22552 | FU41: 0 | FV41: 0 | FW41: 0 | FX41: 0 | FY41: 0 | FZ41: 0 | GA41: 26436 | GB41: 1.2051659e+08
A42: fdip_BTBX | C42: 0.959082 | D42: 50000001 | E42: 52133161 | F42: 62042 | G42: 119854 | H42: 344660 | I42: 256143 | J42: 23688 | K42: 154305 | L42: 27340 | M42: 101649 | N42: 2346228 | O42: 0 | P42: 19760 | Q42: 533789 | R42: 1078083 | S42: 824035 | T42: 1124560 | U42: 849630 | V42: 798971 | W42: 617603 | X42: 529337 | Y42: 230985 | Z42: 151422 | AA42: 195815 | AB42: 205096 | AC42: 140893 | AD42: 79231 | AE42: 77085 | AF42: 278708 | AG42: 301343 | AH42: 542063 | AI42: 145473 | AJ42: 23 | AK42: 6001 | AL42: 10512 | AM42: 0 | AN42: 0 | AO42: 0 | AP42: 0 | AQ42: 7628 | AR42: 0 | AS42: 0 | AT42: 0 | AU42: 0 | AV42: 0 | AW42: 0 | AX42: 0 | AY42: 0 | AZ42: 17213 | BA42: 0 | BB42: 0 | BC42: 0 | BD42: 0 | BE42: 0 | BF42: 0 | BG42: 0 | BH42: 0 | BI42: 0 | BJ42: 0 | BK42: 0 | BL42: 0 | BM42: 0 | BN42: 0 | BO42: 0 | BP42: 0 | BQ42: 0 | BR42: 0 | BS42: 0 | BT42: 0 | BU42: 0 | BV42: 0 | BW42: 0 | BX42: 0 | BY42: 0 | BZ42: 0 | CA42: 0 | CB42: 710015 | CC42: 2346228 | CD42: 17936 | CE42: 321853 | CF42: 415022 | CG42: 984967 | CH42: 618881 | CI42: 733370 | CJ42: 1120592 | CK42: 748513 | CL42: 498083 | CM42: 585137 | CN42: 412864 | CO42: 164059 | CP42: 189717 | CQ42: 115969 | CR42: 74863 | CS42: 370972 | CT42: 108772 | CU42: 214170 | CV42: 659767 | CW42: 337087 | CX42: 30778 | CY42: 5 | CZ42: 0 | DA42: 0 | DB42: 17041 | DC42: 0 | DD42: 0 | DE42: 7628 | DF42: 0 | DG42: 0 | DH42: 0 | DI42: 0 | DJ42: 0 | DK42: 0 | DL42: 0 | DM42: 0 | DN42: 17213 | DO42: 0 | DP42: 0 | DQ42: 0 | DR42: 0 | DS42: 0 | DT42: 0 | DU42: 0 | DV42: 0 | DW42: 0 | DX42: 0 | DY42: 0 | DZ42: 0 | EA42: 0 | EB42: 0 | EC42: 0 | ED42: 0 | EE42: 0 | EF42: 0 | EG42: 0 | EH42: 0 | EI42: 0 | EJ42: 0 | EK42: 0 | EL42: 0 | EM42: 0 | EN42: 0 | EO42: 0 | EP42: 0 | EQ42: 699845 | ER42: 655221 | ES42: 1184176 | ET42: 677734 | EU42: 928189 | EV42: 20476 | EW42: 12755 | EX42: 1164836 | EY42: 145750 | EZ42: 5930 | FA42: 11118 | FB42: 3698 | FC42: 2705 | FD42: 8314 | FE42: 7737 | FF42: 7148 | FG42: 138978 | FH42: 404398 | FI42: 166639 | FJ42: 378637 | FK42: 0 | FL42: 0 | FM42: 39476 | FN42: 0 | FO42: 0 | FP42: 27993 | FQ42: 311168 | FR42: 0 | FS42: 61291232 | FT42: 22552 | FU42: 0 | FV42: 0 | FW42: 0 | FX42: 0 | FY42: 0 | FZ42: 0 | GA42: 26436 | GB42: 1.9449897e+08
...

Sheet data
A1: bench | B1: config | C1: stat | D1: value
A2: client_001 | B2: fdip_BTBX | C2: cumulative-IPC | D2: 1.03678
A3: client_001 | B3: fdip_BTBX | C3: instructions | D3: 50000003 | AH3: Final_fdip_Unified
A4: client_001 | B4: fdip_BTBX | C4: cycles | D4: 48226457
A5: client_001 | B5: fdip_BTBX | C5: L1D-USEFUL | D5: 130820
A6: client_001 | B6: fdip_BTBX | C6: L1D-USELESS | D6: 253391
A7: client_001 | B7: fdip_BTBX | C7: L1I-USEFUL | D7: 102658
A8: client_001 | B8: fdip_BTBX | C8: L1I-USELESS | D8: 41550
A9: client_001 | B9: fdip_BTBX | C9: L2C-USEFUL | D9: 16110
A10: client_001 | B10: fdip_BTBX | C10: L2C-USELESS | D10: 138501
A11: client_001 | B11: fdip_BTBX | C11: LLC-USEFUL | D11: 29902
A12: client_001 | B12: fdip_BTBX | C12: LLC-USELESS | D12: 97266
A13: client_001 | B13: fdip_BTBX | C13: disp-0 | D13: 1439710
A14: client_001 | B14: fdip_BTBX | C14: disp-1 | D14: 0
A15: client_001 | B15: fdip_BTBX | C15: disp-2 | D15: 932
... A29162: server_039 | B29162: no_pdede | C29162: Num_unique_branches | D29162: 2634

Sheet MPKI
H2: no_4KEntryBTBX | Q2: no_4KEQIBTB | Z2: no_4KEntryBTBX
E3: no_convBTB | H3: no_convBTB | Q3: no_pdede | Z3: no_BTBX
E4: instructions | H4: BTB_4D_Misses | I4: BTB_6D_Misses | J4: BTB_8D_Misses | K4: BTB_12D_Misses | L4: BTB_18D_Misses | M4: BTB_25D_Misses | N4: BTB_46D_Misses | O4: BTB_Ret_Misses | Q4: BTB_4D_Misses | R4: BTB_6D_Misses | S4: BTB_8D_Misses | T4: BTB_12D_Misses | U4: BTB_18D_Misses | V4: BTB_25D_Misses | W4: BTB_46D_Misses | X4: BTB_Ret_Misses | Z4: BTB_4D_Misses | AA4: BTB_6D_Misses | AB4: BTB_8D_Misses | AC4: BTB_12D_Misses | AD4: BTB_18D_Misses | AE4: BTB_25D_Misses | AF4: BTB_46D_Misses | AG4: BTB_Ret_Misses | AI4: Total Misses | AJ4: Total Misses | AK4: Total Misses | AM4: MPKI | AN4: MPKI | AO4: MPKI
A5: INT | B5: astar.BigLakes2048 | C5: Client workloads | D5: client_001 | E5: =GETPIVOTDATA("value",pivot!$A$3,"bench",$D5,"config",$E$3,"stat",E$4) -> 50000003 | H5: =GETPIVOTDATA("value",pivot!$A$3,"bench",$D5,"config",$H$3,"stat",H$4) -> 100322 | I5: =GETPIVOTDATA("value",pivot!$A$3,"bench",$D5,"config",$H$3,"stat",I$4) -> 3677 | J5: =GETPIVOTDATA("value",pivot!$A$3,"bench",$D5,"config",$H$3,"stat",J$4) -> 40372 | K5: =GETPIVOTDATA("value",pivot!$A$3,"bench",$D5,"config",$H$3,"stat",K$4) -> 352 | L5: =GETPIVOTDATA("value",pivot!$A$3,"bench",$D5,"config",$H$3,"stat",L$4) -> 3308 | M5: =GETPIVOTDATA("value",pivot!$A$3,"bench",$D5,"config",$H$3,"stat",M$4) -> 216 | N5: =GETPIVOTDATA("value",pivot!$A$3,"bench",$D5,"config",$H$3,"stat",N$4) -> 166 | O5: =GETPIVOTDATA("value",pivot!$A$3,"bench",$D5,"config",$H$3,"stat",O$4) -> 2850 | Q5: =GETPIVOTDATA("value",pivot!$A$3,"bench",$D5,"config",$Q$3,"stat",Q$4) -> 100285 | R5: =GETPIVOTDATA("value",pivot!$A$3,"bench",$D5,"config",$Q$3,"stat",R$4) -> 3594 | S5: =GETPIVOTDATA("value",pivot!$A$3,"bench",$D5,"config",$Q$3,"stat",S$4) -> 43874 | T5: =GETPIVOTDATA("value",pivot!$A$3,"bench",$D5,"config",$Q$3,"stat",T$4) -> 355 | U5: =GETPIVOTDATA("value",pivot!$A$3,"bench",$D5,"config",$Q$3,"stat",U$4) -> 3308 | V5: =GETPIVOTDATA("value",pivot!$A$3,"bench",$D5,"config",$Q$3,"stat",V$4) -> 209 | W5: =GETPIVOTDATA("value",pivot!$A$3,"bench",$D5,"config",$Q$3,"stat",W$4) -> 169 | X5: =GETPIVOTDATA("value",pivot!$A$3,"bench",$D5,"config",$Q$3,"stat",X$4) -> 4660 | Z5: =GETPIVOTDATA("value",pivot!$A$3,"bench",$D5,"config",$Z$3,"stat",Z$4) -> 100262 | AA5: =GETPIVOTDATA("value",pivot!$A$3,"bench",$D5,"config",$Z$3,"stat",AA$4) -> 3612 | AB5: =GETPIVOTDATA("value",pivot!$A$3,"bench",$D5,"config",$Z$3,"stat",AB$4) -> 39945 | AC5: =GETPIVOTDATA("value",pivot!$A$3,"bench",$D5,"config",$Z$3,"stat",AC$4) -> 326 | AD5: =GETPIVOTDATA("value",pivot!$A$3,"bench",$D5,"config",$Z$3,"stat",AD$4) -> 3290 | AE5: =GETPIVOTDATA("value",pivot!$A$3,"bench",$D5,"config",$Z$3,"stat",AE$4) -> 253 | AF5: =GETPIVOTDATA("value",pivot!$A$3,"bench",$D5,"config",$Z$3,"stat",AF$4) -> 194 | AG5: =GETPIVOTDATA("value",pivot!$A$3,"bench",$D5,"config",$Z$3,"stat",AG$4) -> 2802 | AI5: =SUM(H5:O5) -> 151263 | AJ5: =SUM(Q5:X5) -> 156454 | AK5: =SUM(Z5:AG5) -> 150684 | AM5: =(AI5/$E5)*1000 -> 3.0252598 | AN5: =(AJ5/$E5)*1000 -> 3.1290798 | AO5: =(AK5/$E5)*1000 -> 3.0136798
A6: INT | B6: astar.rivers | D6: client_002 | E6: =GETPIVOTDATA("value",pivot!$A$3,"bench",$D6,"config",$E$3,"stat",E$4) -> 50000001 | H6: =GETPIVOTDATA("value",pivot!$A$3,"bench",$D6,"config",$H$3,"stat",H$4) -> 73300 | I6: =GETPIVOTDATA("value",pivot!$A$3,"bench",$D6,"config",$H$3,"stat",I$4) -> 5731 | J6: =GETPIVOTDATA("value",pivot!$A$3,"bench",$D6,"config",$H$3,"stat",J$4) -> 10442 | K6: =GETPIVOTDATA("value",pivot!$A$3,"bench",$D6,"config",$H$3,"stat",K$4) -> 7826 | L6: =GETPIVOTDATA("value",pivot!$A$3,"bench",$D6,"config",$H$3,"stat",L$4) -> 4261 | M6: =GETPIVOTDATA("value",pivot!$A$3,"bench",$D6,"config",$H$3,"stat",M$4) -> 13803 | N6: =GETPIVOTDATA("value",pivot!$A$3,"bench",$D6,"config",$H$3,"stat",N$4) -> 8263 | O6: =GETPIVOTDATA("value",pivot!$A$3,"bench",$D6,"config",$H$3,"stat",O$4) -> 8725 | Q6: =GETPIVOTDATA("value",pivot!$A$3,"bench",$D6,"config",$Q$3,"stat",Q$4) -> 61611 | R6: =GETPIVOTDATA("value",pivot!$A$3,"bench",$D6,"config",$Q$3,"stat",R$4) -> 3208 | S6: =GETPIVOTDATA("value",pivot!$A$3,"bench",$D6,"config",$Q$3,"stat",S$4) -> 4020 | T6: =GETPIVOTDATA("value",pivot!$A$3,"bench",$D6,"config",$Q$3,"stat",T$4) -> 2265 | U6: =GETPIVOTDATA("value",pivot!$A$3,"bench",$D6,"config",$Q$3,"stat",U$4) -> 1188 | V6: =GETPIVOTDATA("value",pivot!$A$3,"bench",$D6,"config",$Q$3,"stat",V$4) -> 5063 | W6: =GETPIVOTDATA("value",pivot!$A$3,"bench",$D6,"config",$Q$3,"stat",W$4) -> 5143 | X6: =GETPIVOTDATA("value",pivot!$A$3,"bench",$D6,"config",$Q$3,"stat",X$4) -> 1569 | Z6: =GETPIVOTDATA("value",pivot!$A$3,"bench",$D6,"config",$Z$3,"stat",Z$4) -> 61989 | AA6: =GETPIVOTDATA("value",pivot!$A$3,"bench",$D6,"config",$Z$3,"stat",AA$4) -> 2837 | AB6: =GETPIVOTDATA("value",pivot!$A$3,"bench",$D6,"config",$Z$3,"stat",AB$4) -> 3427 | AC6: =GETPIVOTDATA("value",pivot!$A$3,"bench",$D6,"config",$Z$3,"stat",AC$4) -> 1853 | AD6: =GETPIVOTDATA("value",pivot!$A$3,"bench",$D6,"config",$Z$3,"stat",AD$4) -> 937 | AE6: =GETPIVOTDATA("value",pivot!$A$3,"bench",$D6,"config",$Z$3,"stat",AE$4) -> 7573 | AF6: =GETPIVOTDATA("value",pivot!$A$3,"bench",$D6,"config",$Z$3,"stat",AF$4) -> 7452 | AG6: =GETPIVOTDATA("value",pivot!$A$3,"bench",$D6,"config",$Z$3,"stat",AG$4) -> 896 | AI6: =SUM(H6:O6) -> 132351 | AJ6: =SUM(Q6:X6) -> 84067 | AK6: =SUM(Z6:AG6) -> 86964 | AM6: =(AI6/$E6)*1000 -> 2.6470199 | AN6: =(AJ6/$E6)*1000 -> 1.68134 | AO6: =(AK6/$E6)*1000 -> 1.73928
A7: FP | B7: bwaves | D7: client_003 | E7: =GETPIVOTDATA("value",pivot!$A$3,"bench",$D7,"config",$E$3,"stat",E$4) -> 50000001 | H7: =GETPIVOTDATA("value",pivot!$A$3,"bench",$D7,"config",$H$3,"stat",H$4) -> 178414 | I7: =GETPIVOTDATA("value",pivot!$A$3,"bench",$D7,"config",$H$3,"stat",I$4) -> 4673 | J7: =GETPIVOTDATA("value",pivot!$A$3,"bench",$D7,"config",$H$3,"stat",J$4) -> 6442 | K7: =GETPIVOTDATA("value",pivot!$A$3,"bench",$D7,"config",$H$3,"stat",K$4) -> 4007 | L7: =GETPIVOTDATA("value",pivot!$A$3,"bench",$D7,"config",$H$3,"stat",L$4) -> 2296 | M7: =GETPIVOTDATA("value",pivot!$A$3,"bench",$D7,"config",$H$3,"stat",M$4) -> 9282 | N7: =GETPIVOTDATA("value",pivot!$A$3,"bench",$D7,"config",$H$3,"stat",N$4) -> 2688 | O7: =GETPIVOTDATA("value",pivot!$A$3,"bench",$D7,"config",$H$3,"stat",O$4) -> 5194 | Q7: =GETPIVOTDATA("value",pivot!$A$3,"bench",$D7,"config",$Q$3,"stat",Q$4) -> 174657 | R7: =GETPIVOTDATA("value",pivot!$A$3,"bench",$D7,"config",$Q$3,"stat",R$4) -> 3395 | S7: =GETPIVOTDATA("value",pivot!$A$3,"bench",$D7,"config",$Q$3,"stat",S$4) -> 3802 | T7: =GETPIVOTDATA("value",pivot!$A$3,"bench",$D7,"config",$Q$3,"stat",T$4) -> 1780 | U7: =GETPIVOTDATA("value",pivot!$A$3,"bench",$D7,"config",$Q$3,"stat",U$4) -> 1144 | V7: =GETPIVOTDATA("value",pivot!$A$3,"bench",$D7,"config",$Q$3,"stat",V$4) -> 5878 | W7: =GETPIVOTDATA("value",pivot!$A$3,"bench",$D7,"config",$Q$3,"stat",W$4) -> 1547 | X7: =GETPIVOTDATA("value",pivot!$A$3,"bench",$D7,"config",$Q$3,"stat",X$4) -> 2289 | Z7: =GETPIVOTDATA("value",pivot!$A$3,"bench",$D7,"config",$Z$3,"stat",Z$4) -> 175334 | AA7: =GETPIVOTDATA("value",pivot!$A$3,"bench",$D7,"config",$Z$3,"stat",AA$4) -> 3011 | AB7: =GETPIVOTDATA("value",pivot!$A$3,"bench",$D7,"config",$Z$3,"stat",AB$4) -> 3361 | AC7: =GETPIVOTDATA("value",pivot!$A$3,"bench",$D7,"config",$Z$3,"stat",AC$4) -> 1591 | AD7: =GETPIVOTDATA("value",pivot!$A$3,"bench",$D7,"config",$Z$3,"stat",AD$4) -> 1110 | AE7: =GETPIVOTDATA("value",pivot!$A$3,"bench",$D7,"config",$Z$3,"stat",AE$4) -> 7531 | AF7: =GETPIVOTDATA("value",pivot!$A$3,"bench",$D7,"config",$Z$3,"stat",AF$4) -> 2451 | AG7: =GETPIVOTDATA("value",pivot!$A$3,"bench",$D7,"config",$Z$3,"stat",AG$4) -> 1198 | AI7: =SUM(H7:O7) -> 212996 | AJ7: =SUM(Q7:X7) -> 194492 | AK7: =SUM(Z7:AG7) -> 195587 | AM7: =(AI7/$E7)*1000 -> 4.2599199 | AN7: =(AJ7/$E7)*1000 -> 3.8898399 | AO7: =(AK7/$E7)*1000 -> 3.9117399
